Workbook

Sheet Sheet1
B1: هم وحزن | C1: توفى شخص عزيز | D1: اشعر بالوحدة | E1: انتهى صبري | F1: اشعر بالظلم | G1: اشعر بالندم | H1: احتاج الى الامل | I1: اشعر بالعجز والكسل | J1: اشعر بالقلق والخوف | K1: اشعر بضيق الرزق | L1: ارتكبت ذنب | M1: احتاج الى الرضا والقناعة | N1: ارغب في التغيير وبداية جديدة | O1: كيف اتعامل مع الناس | P1: اشعر بالخذلان وعدم التقدير | Q1: اريد التقرب من الله
A2: سورة البقرة | B2: FALSE | C2: FALSE | D2: FALSE | E2: FALSE | F2: FALSE | G2: FALSE | H2: FALSE | I2: FALSE | J2: FALSE | K2: FALSE | L2: FALSE | M2: FALSE | N2: FALSE | O2: FALSE | P2: FALSE | Q2: FALSE
A3: ذَٰلِكَ الْكِتَابُ لَا رَيْبَ ۛ فِيهِ ۛ هُدًى لِلْمُتَّقِينَ | B3: FALSE | C3: FALSE | D3: FALSE | E3: FALSE | F3: FALSE | G3: FALSE | H3: FALSE | I3: TRUE | J3: FALSE | K3: TRUE | L3: FALSE | M3: FALSE | N3: TRUE | O3: FALSE | P3: FALSE | Q3: FALSE
A4: الَّذِينَ يُؤْمِنُونَ بِالْغَيْبِ وَيُقِيمُونَ الصَّلَاةَ وَمِمَّا رَزَقْنَاهُمْ يُنْفِقُونَ {3} وَالَّذِينَ يُؤْمِنُونَ بِمَا أُنْزِلَ إِلَيْكَ وَمَا أُنْزِلَ مِنْ قَبْلِكَ وَبِالْآخِرَةِ هُمْ يُوقِنُونَ {4} أُولَٰئِكَ عَلَىٰ هُدًى مِنْ رَبِّهِمْ ۖ وَأُولَٰئِكَ هُمُ الْمُفْلِحُونَ {5} سورة البقرة | B4: FALSE | C4: FALSE | D4: FALSE | E4: FALSE | F4: FALSE | G4: FALSE | H4: TRUE | I4: FALSE | J4: FALSE | K4: FALSE | L4: FALSE | M4: FALSE | N4: FALSE | O4: FALSE | P4: FALSE | Q4: TRUE
A5: وَمِنَ النَّاسِ مَنْ يَقُولُ آمَنَّا بِاللَّهِ وَبِالْيَوْمِ الْآخِرِ وَمَا هُمْ بِمُؤْمِنِينَ {8} سورة البقرة | B5: FALSE | C5: FALSE | D5: FALSE | E5: FALSE | F5: FALSE | G5: FALSE | H5: FALSE | I5: FALSE | J5: FALSE | K5: FALSE | L5: FALSE | M5: FALSE | N5: FALSE | O5: FALSE | P5: FALSE | Q5: FALSE
A6: وَإِذَا قِيلَ لَهُمْ لَا تُفْسِدُوا فِي الْأَرْضِ قَالُوا إِنَّمَا نَحْنُ مُصْلِحُونَ {11} أَلَا إِنَّهُمْ هُمُ الْمُفْسِدُونَ وَلَٰكِنْ لَا يَشْعُرُونَ {12} سورة البقرة | B6: FALSE | C6: FALSE | D6: FALSE | E6: FALSE | F6: FALSE | G6: FALSE | H6: TRUE | I6: FALSE | J6: TRUE | K6: FALSE | L6: FALSE | M6: FALSE | N6: FALSE | O6: FALSE | P6: FALSE | Q6: FALSE
A7: إِنَّ اللَّهَ عَلَىٰ كُلِّ شَيْءٍ قَدِيرٌ {20} سورة البقرة | B7: FALSE | C7: FALSE | D7: FALSE | E7: FALSE | F7: FALSE | G7: FALSE | H7: FALSE | I7: FALSE | J7: FALSE | K7: FALSE | L7: FALSE | M7: TRUE | N7: FALSE | O7: FALSE | P7: TRUE | Q7: FALSE

Sheet Sheet2
A1: =IF(#REF!="","",#REF!) -> #REF! | B1: =IF(#REF!="","",#REF!) -> #REF! | C1: =IF(Sheet1!C2="","",Sheet1!C2) -> FALSE | D1: =IF(Sheet1!D2="","",Sheet1!D2) -> FALSE | E1: =IF(Sheet1!E2="","",Sheet1!E2) -> FALSE | F1: =IF(Sheet1!F2="","",Sheet1!F2) -> FALSE | G1: =IF(Sheet1!G2="","",Sheet1!G2) -> FALSE | H1: =IF(Sheet1!H2="","",Sheet1!H2) -> FALSE | I1: =IF(#REF!="","",#REF!) -> #REF! | J1: =IF(Sheet1!I2="","",Sheet1!I2) -> FALSE | K1: =IF(Sheet1!J2="","",Sheet1!J2) -> FALSE | L1: =IF(Sheet1!K2="","",Sheet1!K2) -> FALSE | M1: =IF(Sheet1!L2="","",Sheet1!L2) -> FALSE
A2: =IF(Sheet1!A3="","",Sheet1!A3) -> ذَٰلِكَ الْكِتَابُ لَا رَيْبَ ۛ فِيهِ ۛ هُدًى لِلْمُتَّقِينَ | B2: =IF(OR(Sheet1!B3="",Sheet1!B3=FALSE),"",Sheet1!B3) | C2: =IF(OR(Sheet1!C3="",Sheet1!C3=FALSE),"",Sheet1!C3) | D2: =IF(OR(Sheet1!D3="",Sheet1!D3=FALSE),"",Sheet1!D3) | E2: =IF(OR(Sheet1!E3="",Sheet1!E3=FALSE),"",Sheet1!E3) | F2: =IF(OR(Sheet1!F3="",Sheet1!F3=FALSE),"",Sheet1!F3) | G2: =IF(OR(Sheet1!G3="",Sheet1!G3=FALSE),"",Sheet1!G3) | H2: =IF(OR(Sheet1!H3="",Sheet1!H3=FALSE),"",Sheet1!H3) | I2: =IF(OR(#REF!="",#REF!=FALSE),"",#REF!) -> #REF! | J2: =IF(OR(Sheet1!I3="",Sheet1!I3=FALSE),"",Sheet1!I3) -> TRUE | K2: =IF(OR(Sheet1!J3="",Sheet1!J3=FALSE),"",Sheet1!J3) | L2: =IF(OR(Sheet1!K3="",Sheet1!K3=FALSE),"",Sheet1!K3) -> TRUE | M2: =IF(OR(Sheet1!L3="",Sheet1!L3=FALSE),"",Sheet1!L3)
A3: =IF(#REF!="","",#REF!) -> #REF! | B3: =IF(OR(#REF!="",#REF!=FALSE),"",#REF!) -> #REF! | C3: =IF(OR(#REF!="",#REF!=FALSE),"",#REF!) -> #REF! | D3: =IF(OR(#REF!="",#REF!=FALSE),"",#REF!) -> #REF! | E3: =IF(OR(#REF!="",#REF!=FALSE),"",#REF!) -> #REF! | F3: =IF(OR(#REF!="",#REF!=FALSE),"",#REF!) -> #REF! | G3: =IF(OR(#REF!="",#REF!=FALSE),"",#REF!) -> #REF! | H3: =IF(OR(#REF!="",#REF!=FALSE),"",#REF!) -> #REF! | I3: =IF(OR(#REF!="",#REF!=FALSE),"",#REF!) -> #REF! | ... M3: =IF(OR(#REF!="",#REF!=FALSE),"",#REF!) -> #REF!
A4: =IF(Sheet1!A4="","",Sheet1!A4) -> الَّذِينَ يُؤْمِنُونَ بِالْغَيْبِ وَيُقِيمُونَ الصَّلَاةَ وَمِمَّا رَزَقْنَاهُمْ يُنْفِقُونَ {3} وَالَّذِينَ يُؤْمِنُونَ بِمَا أُنْزِلَ إِلَيْكَ وَمَا أُنْزِلَ مِنْ قَبْلِكَ وَبِالْآخِرَةِ هُمْ يُوقِنُونَ {4} أُولَٰئِكَ عَلَىٰ هُدًى مِنْ رَبِّهِمْ ۖ وَأُولَٰئِكَ هُمُ الْمُفْلِحُونَ {5} سورة البقرة | B4: =IF(OR(Sheet1!B4="",Sheet1!B4=FALSE),"",Sheet1!B4) | C4: =IF(OR(Sheet1!C4="",Sheet1!C4=FALSE),"",Sheet1!C4) | D4: =IF(OR(Sheet1!D4="",Sheet1!D4=FALSE),"",Sheet1!D4) | E4: =IF(OR(Sheet1!E4="",Sheet1!E4=FALSE),"",Sheet1!E4) | F4: =IF(OR(Sheet1!F4="",Sheet1!F4=FALSE),"",Sheet1!F4) | G4: =IF(OR(Sheet1!G4="",Sheet1!G4=FALSE),"",Sheet1!G4) | H4: =IF(OR(Sheet1!H4="",Sheet1!H4=FALSE),"",Sheet1!H4) -> TRUE | I4: =IF(OR(#REF!="",#REF!=FALSE),"",#REF!) -> #REF! | J4: =IF(OR(Sheet1!I4="",Sheet1!I4=FALSE),"",Sheet1!I4) | K4: =IF(OR(Sheet1!J4="",Sheet1!J4=FALSE),"",Sheet1!J4) | L4: =IF(OR(Sheet1!K4="",Sheet1!K4=FALSE),"",Sheet1!K4) | M4: =IF(OR(Sheet1!L4="",Sheet1!L4=FALSE),"",Sheet1!L4)
A5: =IF(Sheet1!A5="","",Sheet1!A5) -> وَمِنَ النَّاسِ مَنْ يَقُولُ آمَنَّا بِاللَّهِ وَبِالْيَوْمِ الْآخِرِ وَمَا هُمْ بِمُؤْمِنِينَ {8} سورة البقرة | B5: =IF(OR(Sheet1!B5="",Sheet1!B5=FALSE),"",Sheet1!B5) | C5: =IF(OR(Sheet1!C5="",Sheet1!C5=FALSE),"",Sheet1!C5) | D5: =IF(OR(Sheet1!D5="",Sheet1!D5=FALSE),"",Sheet1!D5) | E5: =IF(OR(Sheet1!E5="",Sheet1!E5=FALSE),"",Sheet1!E5) | F5: =IF(OR(Sheet1!F5="",Sheet1!F5=FALSE),"",Sheet1!F5) | G5: =IF(OR(Sheet1!G5="",Sheet1!G5=FALSE),"",Sheet1!G5) | H5: =IF(OR(Sheet1!H5="",Sheet1!H5=FALSE),"",Sheet1!H5) | I5: =IF(OR(#REF!="",#REF!=FALSE),"",#REF!) -> #REF! | J5: =IF(OR(Sheet1!I5="",Sheet1!I5=FALSE),"",Sheet1!I5) | K5: =IF(OR(Sheet1!J5="",Sheet1!J5=FALSE),"",Sheet1!J5) | L5: =IF(OR(Sheet1!K5="",Sheet1!K5=FALSE),"",Sheet1!K5) | M5: =IF(OR(Sheet1!L5="",Sheet1!L5=FALSE),"",Sheet1!L5)
A6: =IF(Sheet1!A6="","",Sheet1!A6) -> وَإِذَا قِيلَ لَهُمْ لَا تُفْسِدُوا فِي الْأَرْضِ قَالُوا إِنَّمَا نَحْنُ مُصْلِحُونَ {11} أَلَا إِنَّهُمْ هُمُ الْمُفْسِدُونَ وَلَٰكِنْ لَا يَشْعُرُونَ {12} سورة البقرة | B6: =IF(OR(Sheet1!B6="",Sheet1!B6=FALSE),"",Sheet1!B6) | C6: =IF(OR(Sheet1!C6="",Sheet1!C6=FALSE),"",Sheet1!C6) | D6: =IF(OR(Sheet1!D6="",Sheet1!D6=FALSE),"",Sheet1!D6) | E6: =IF(OR(Sheet1!E6="",Sheet1!E6=FALSE),"",Sheet1!E6) | F6: =IF(OR(Sheet1!F6="",Sheet1!F6=FALSE),"",Sheet1!F6) | G6: =IF(OR(Sheet1!G6="",Sheet1!G6=FALSE),"",Sheet1!G6) | H6: =IF(OR(Sheet1!H6="",Sheet1!H6=FALSE),"",Sheet1!H6) -> TRUE | I6: =IF(OR(#REF!="",#REF!=FALSE),"",#REF!) -> #REF! | J6: =IF(OR(Sheet1!I6="",Sheet1!I6=FALSE),"",Sheet1!I6) | K6: =IF(OR(Sheet1!J6="",Sheet1!J6=FALSE),"",Sheet1!J6) -> TRUE | L6: =IF(OR(Sheet1!K6="",Sheet1!K6=FALSE),"",Sheet1!K6) | M6: =IF(OR(Sheet1!L6="",Sheet1!L6=FALSE),"",Sheet1!L6)
A7: =IF(Sheet1!A7="","",Sheet1!A7) -> إِنَّ اللَّهَ عَلَىٰ كُلِّ شَيْءٍ قَدِيرٌ {20} سورة البقرة | B7: =IF(OR(Sheet1!B7="",Sheet1!B7=FALSE),"",Sheet1!B7) | C7: =IF(OR(Sheet1!C7="",Sheet1!C7=FALSE),"",Sheet1!C7) | D7: =IF(OR(Sheet1!D7="",Sheet1!D7=FALSE),"",Sheet1!D7) | E7: =IF(OR(Sheet1!E7="",Sheet1!E7=FALSE),"",Sheet1!E7) | F7: =IF(OR(Sheet1!F7="",Sheet1!F7=FALSE),"",Sheet1!F7) | G7: =IF(OR(Sheet1!G7="",Sheet1!G7=FALSE),"",Sheet1!G7) | H7: =IF(OR(Sheet1!H7="",Sheet1!H7=FALSE),"",Sheet1!H7) | I7: =IF(OR(#REF!="",#REF!=FALSE),"",#REF!) -> #REF! | J7: =IF(OR(Sheet1!I7="",Sheet1!I7=FALSE),"",Sheet1!I7) | K7: =IF(OR(Sheet1!J7="",Sheet1!J7=FALSE),"",Sheet1!J7) | L7: =IF(OR(Sheet1!K7="",Sheet1!K7=FALSE),"",Sheet1!K7) | M7: =IF(OR(Sheet1!L7="",Sheet1!L7=FALSE),"",Sheet1!L7)
A8: =IF(Sheet1!A51="","",Sheet1!A51) | B8: =IF(OR(Sheet1!B51="",Sheet1!B51=FALSE),"",Sheet1!B51) | C8: =IF(OR(Sheet1!C51="",Sheet1!C51=FALSE),"",Sheet1!C51) | D8: =IF(OR(Sheet1!D51="",Sheet1!D51=FALSE),"",Sheet1!D51) | E8: =IF(OR(Sheet1!E51="",Sheet1!E51=FALSE),"",Sheet1!E51) | F8: =IF(OR(Sheet1!F51="",Sheet1!F51=FALSE),"",Sheet1!F51) | G8: =IF(OR(Sheet1!G51="",Sheet1!G51=FALSE),"",Sheet1!G51) | H8: =IF(OR(Sheet1!H51="",Sheet1!H51=FALSE),"",Sheet1!H51) | I8: =IF(OR(#REF!="",#REF!=FALSE),"",#REF!) -> #REF! | J8: =IF(OR(Sheet1!I51="",Sheet1!I51=FALSE),"",Sheet1!I51) | K8: =IF(OR(Sheet1!J51="",Sheet1!J51=FALSE),"",Sheet1!J51) | L8: =IF(OR(Sheet1!K51="",Sheet1!K51=FALSE),"",Sheet1!K51) | M8: =IF(OR(Sheet1!L51="",Sheet1!L51=FALSE),"",Sheet1!L51)
A9: =IF(Sheet1!A8="","",Sheet1!A8) | B9: =IF(OR(Sheet1!B8="",Sheet1!B8=FALSE),"",Sheet1!B8) | C9: =IF(OR(Sheet1!C8="",Sheet1!C8=FALSE),"",Sheet1!C8) | D9: =IF(OR(Sheet1!D8="",Sheet1!D8=FALSE),"",Sheet1!D8) | E9: =IF(OR(Sheet1!E8="",Sheet1!E8=FALSE),"",Sheet1!E8) | F9: =IF(OR(Sheet1!F8="",Sheet1!F8=FALSE),"",Sheet1!F8) | G9: =IF(OR(Sheet1!G8="",Sheet1!G8=FALSE),"",Sheet1!G8) | H9: =IF(OR(Sheet1!H8="",Sheet1!H8=FALSE),"",Sheet1!H8) | I9: =IF(OR(#REF!="",#REF!=FALSE),"",#REF!) -> #REF! | J9: =IF(OR(Sheet1!I8="",Sheet1!I8=FALSE),"",Sheet1!I8) | K9: =IF(OR(Sheet1!J8="",Sheet1!J8=FALSE),"",Sheet1!J8) | L9: =IF(OR(Sheet1!K8="",Sheet1!K8=FALSE),"",Sheet1!K8) | M9: =IF(OR(Sheet1!L8="",Sheet1!L8=FALSE),"",Sheet1!L8)
A10: =IF(Sheet1!A9="","",Sheet1!A9) | B10: =IF(OR(Sheet1!B9="",Sheet1!B9=FALSE),"",Sheet1!B9) | C10: =IF(OR(Sheet1!C9="",Sheet1!C9=FALSE),"",Sheet1!C9) | D10: =IF(OR(Sheet1!D9="",Sheet1!D9=FALSE),"",Sheet1!D9) | E10: =IF(OR(Sheet1!E9="",Sheet1!E9=FALSE),"",Sheet1!E9) | F10: =IF(OR(Sheet1!F9="",Sheet1!F9=FALSE),"",Sheet1!F9) | G10: =IF(OR(Sheet1!G9="",Sheet1!G9=FALSE),"",Sheet1!G9) | H10: =IF(OR(Sheet1!H9="",Sheet1!H9=FALSE),"",Sheet1!H9) | I10: =IF(OR(#REF!="",#REF!=FALSE),"",#REF!) -> #REF! | J10: =IF(OR(Sheet1!I9="",Sheet1!I9=FALSE),"",Sheet1!I9) | K10: =IF(OR(Sheet1!J9="",Sheet1!J9=FALSE),"",Sheet1!J9) | L10: =IF(OR(Sheet1!K9="",Sheet1!K9=FALSE),"",Sheet1!K9) | M10: =IF(OR(Sheet1!L9="",Sheet1!L9=FALSE),"",Sheet1!L9)
A11: =IF(#REF!="","",#REF!) -> #REF! | B11: =IF(OR(#REF!="",#REF!=FALSE),"",#REF!) -> #REF! | C11: =IF(OR(#REF!="",#REF!=FALSE),"",#REF!) -> #REF! | D11: =IF(OR(#REF!="",#REF!=FALSE),"",#REF!) -> #REF! | E11: =IF(OR(#REF!="",#REF!=FALSE),"",#REF!) -> #REF! | F11: =IF(OR(#REF!="",#REF!=FALSE),"",#REF!) -> #REF! | G11: =IF(OR(#REF!="",#REF!=FALSE),"",#REF!) -> #REF! | H11: =IF(OR(#REF!="",#REF!=FALSE),"",#REF!) -> #REF! | I11: =IF(OR(#REF!="",#REF!=FALSE),"",#REF!) -> #REF! | ... M11: =IF(OR(#REF!="",#REF!=FALSE),"",#REF!) -> #REF!
A12: =IF(Sheet1!A10="","",Sheet1!A10) | B12: =IF(OR(Sheet1!B10="",Sheet1!B10=FALSE),"",Sheet1!B10) | C12: =IF(OR(Sheet1!C10="",Sheet1!C10=FALSE),"",Sheet1!C10) | D12: =IF(OR(Sheet1!D10="",Sheet1!D10=FALSE),"",Sheet1!D10) | E12: =IF(OR(Sheet1!E10="",Sheet1!E10=FALSE),"",Sheet1!E10) | F12: =IF(OR(Sheet1!F10="",Sheet1!F10=FALSE),"",Sheet1!F10) | G12: =IF(OR(Sheet1!G10="",Sheet1!G10=FALSE),"",Sheet1!G10) | H12: =IF(OR(Sheet1!H10="",Sheet1!H10=FALSE),"",Sheet1!H10) | I12: =IF(OR(#REF!="",#REF!=FALSE),"",#REF!) -> #REF! | J12: =IF(OR(Sheet1!I10="",Sheet1!I10=FALSE),"",Sheet1!I10) | K12: =IF(OR(Sheet1!J10="",Sheet1!J10=FALSE),"",Sheet1!J10) | L12: =IF(OR(Sheet1!K10="",Sheet1!K10=FALSE),"",Sheet1!K10) | M12: =IF(OR(Sheet1!L10="",Sheet1!L10=FALSE),"",Sheet1!L10)
A13: =IF(Sheet1!A11="","",Sheet1!A11) | B13: =IF(OR(Sheet1!B11="",Sheet1!B11=FALSE),"",Sheet1!B11) | C13: =IF(OR(Sheet1!C11="",Sheet1!C11=FALSE),"",Sheet1!C11) | D13: =IF(OR(Sheet1!D11="",Sheet1!D11=FALSE),"",Sheet1!D11) | E13: =IF(OR(Sheet1!E11="",Sheet1!E11=FALSE),"",Sheet1!E11) | F13: =IF(OR(Sheet1!F11="",Sheet1!F11=FALSE),"",Sheet1!F11) | G13: =IF(OR(Sheet1!G11="",Sheet1!G11=FALSE),"",Sheet1!G11) | H13: =IF(OR(Sheet1!H11="",Sheet1!H11=FALSE),"",Sheet1!H11) | I13: =IF(OR(#REF!="",#REF!=FALSE),"",#REF!) -> #REF! | J13: =IF(OR(Sheet1!I11="",Sheet1!I11=FALSE),"",Sheet1!I11) | K13: =IF(OR(Sheet1!J11="",Sheet1!J11=FALSE),"",Sheet1!J11) | L13: =IF(OR(Sheet1!K11="",Sheet1!K11=FALSE),"",Sheet1!K11) | M13: =IF(OR(Sheet1!L11="",Sheet1!L11=FALSE),"",Sheet1!L11)
A14: =IF(Sheet1!A12="","",Sheet1!A12) | B14: =IF(OR(Sheet1!B12="",Sheet1!B12=FALSE),"",Sheet1!B12) | C14: =IF(OR(Sheet1!C12="",Sheet1!C12=FALSE),"",Sheet1!C12) | D14: =IF(OR(Sheet1!D12="",Sheet1!D12=FALSE),"",Sheet1!D12) | E14: =IF(OR(Sheet1!E12="",Sheet1!E12=FALSE),"",Sheet1!E12) | F14: =IF(OR(Sheet1!F12="",Sheet1!F12=FALSE),"",Sheet1!F12) | G14: =IF(OR(Sheet1!G12="",Sheet1!G12=FALSE),"",Sheet1!G12) | H14: =IF(OR(Sheet1!H12="",Sheet1!H12=FALSE),"",Sheet1!H12) | I14: =IF(OR(#REF!="",#REF!=FALSE),"",#REF!) -> #REF! | J14: =IF(OR(Sheet1!I12="",Sheet1!I12=FALSE),"",Sheet1!I12) | K14: =IF(OR(Sheet1!J12="",Sheet1!J12=FALSE),"",Sheet1!J12) | L14: =IF(OR(Sheet1!K12="",Sheet1!K12=FALSE),"",Sheet1!K12) | M14: =IF(OR(Sheet1!L12="",Sheet1!L12=FALSE),"",Sheet1!L12)
A15: =IF(Sheet1!A13="","",Sheet1!A13) | B15: =IF(OR(Sheet1!B13="",Sheet1!B13=FALSE),"",Sheet1!B13) | C15: =IF(OR(Sheet1!C13="",Sheet1!C13=FALSE),"",Sheet1!C13) | D15: =IF(OR(Sheet1!D13="",Sheet1!D13=FALSE),"",Sheet1!D13) | E15: =IF(OR(Sheet1!E13="",Sheet1!E13=FALSE),"",Sheet1!E13) | F15: =IF(OR(Sheet1!F13="",Sheet1!F13=FALSE),"",Sheet1!F13) | G15: =IF(OR(Sheet1!G13="",Sheet1!G13=FALSE),"",Sheet1!G13) | H15: =IF(OR(Sheet1!H13="",Sheet1!H13=FALSE),"",Sheet1!H13) | I15: =IF(OR(#REF!="",#REF!=FALSE),"",#REF!) -> #REF! | J15: =IF(OR(Sheet1!I13="",Sheet1!I13=FALSE),"",Sheet1!I13) | K15: =IF(OR(Sheet1!J13="",Sheet1!J13=FALSE),"",Sheet1!J13) | L15: =IF(OR(Sheet1!K13="",Sheet1!K13=FALSE),"",Sheet1!K13) | M15: =IF(OR(Sheet1!L13="",Sheet1!L13=FALSE),"",Sheet1!L13)
A16: =IF(Sheet1!A14="","",Sheet1!A14) | B16: =IF(OR(Sheet1!B14="",Sheet1!B14=FALSE),"",Sheet1!B14) | C16: =IF(OR(Sheet1!C14="",Sheet1!C14=FALSE),"",Sheet1!C14) | D16: =IF(OR(Sheet1!D14="",Sheet1!D14=FALSE),"",Sheet1!D14) | E16: =IF(OR(Sheet1!E14="",Sheet1!E14=FALSE),"",Sheet1!E14) | F16: =IF(OR(Sheet1!F14="",Sheet1!F14=FALSE),"",Sheet1!F14) | G16: =IF(OR(Sheet1!G14="",Sheet1!G14=FALSE),"",Sheet1!G14) | H16: =IF(OR(Sheet1!H14="",Sheet1!H14=FALSE),"",Sheet1!H14) | I16: =IF(OR(#REF!="",#REF!=FALSE),"",#REF!) -> #REF! | J16: =IF(OR(Sheet1!I14="",Sheet1!I14=FALSE),"",Sheet1!I14) | K16: =IF(OR(Sheet1!J14="",Sheet1!J14=FALSE),"",Sheet1!J14) | L16: =IF(OR(Sheet1!K14="",Sheet1!K14=FALSE),"",Sheet1!K14) | M16: =IF(OR(Sheet1!L14="",Sheet1!L14=FALSE),"",Sheet1!L14)
A17: =IF(Sheet1!A15="","",Sheet1!A15) | B17: =IF(OR(Sheet1!B15="",Sheet1!B15=FALSE),"",Sheet1!B15) | C17: =IF(OR(Sheet1!C15="",Sheet1!C15=FALSE),"",Sheet1!C15) | D17: =IF(OR(Sheet1!D15="",Sheet1!D15=FALSE),"",Sheet1!D15) | E17: =IF(OR(Sheet1!E15="",Sheet1!E15=FALSE),"",Sheet1!E15) | F17: =IF(OR(Sheet1!F15="",Sheet1!F15=FALSE),"",Sheet1!F15) | G17: =IF(OR(Sheet1!G15="",Sheet1!G15=FALSE),"",Sheet1!G15) | H17: =IF(OR(Sheet1!H15="",Sheet1!H15=FALSE),"",Sheet1!H15) | I17: =IF(OR(#REF!="",#REF!=FALSE),"",#REF!) -> #REF! | J17: =IF(OR(Sheet1!I15="",Sheet1!I15=FALSE),"",Sheet1!I15) | K17: =IF(OR(Sheet1!J15="",Sheet1!J15=FALSE),"",Sheet1!J15) | L17: =IF(OR(Sheet1!K15="",Sheet1!K15=FALSE),"",Sheet1!K15) | M17: =IF(OR(Sheet1!L15="",Sheet1!L15=FALSE),"",Sheet1!L15)
A18: =IF(Sheet1!A16="","",Sheet1!A16) | B18: =IF(OR(Sheet1!B16="",Sheet1!B16=FALSE),"",Sheet1!B16) | C18: =IF(OR(Sheet1!C16="",Sheet1!C16=FALSE),"",Sheet1!C16) | D18: =IF(OR(Sheet1!D16="",Sheet1!D16=FALSE),"",Sheet1!D16) | E18: =IF(OR(Sheet1!E16="",Sheet1!E16=FALSE),"",Sheet1!E16) | F18: =IF(OR(Sheet1!F16="",Sheet1!F16=FALSE),"",Sheet1!F16) | G18: =IF(OR(Sheet1!G16="",Sheet1!G16=FALSE),"",Sheet1!G16) | H18: =IF(OR(Sheet1!H16="",Sheet1!H16=FALSE),"",Sheet1!H16) | I18: =IF(OR(#REF!="",#REF!=FALSE),"",#REF!) -> #REF! | J18: =IF(OR(Sheet1!I16="",Sheet1!I16=FALSE),"",Sheet1!I16) | K18: =IF(OR(Sheet1!J16="",Sheet1!J16=FALSE),"",Sheet1!J16) | L18: =IF(OR(Sheet1!K16="",Sheet1!K16=FALSE),"",Sheet1!K16) | M18: =IF(OR(Sheet1!L16="",Sheet1!L16=FALSE),"",Sheet1!L16)
A19: =IF(#REF!="","",#REF!) -> #REF! | B19: =IF(OR(#REF!="",#REF!=FALSE),"",#REF!) -> #REF! | C19: =IF(OR(#REF!="",#REF!=FALSE),"",#REF!) -> #REF! | D19: =IF(OR(#REF!="",#REF!=FALSE),"",#REF!) -> #REF! | E19: =IF(OR(#REF!="",#REF!=FALSE),"",#REF!) -> #REF! | F19: =IF(OR(#REF!="",#REF!=FALSE),"",#REF!) -> #REF! | G19: =IF(OR(#REF!="",#REF!=FALSE),"",#REF!) -> #REF! | H19: =IF(OR(#REF!="",#REF!=FALSE),"",#REF!) -> #REF! | I19: =IF(OR(#REF!="",#REF!=FALSE),"",#REF!) -> #REF! | ... M19: =IF(OR(#REF!="",#REF!=FALSE),"",#REF!) -> #REF!
A20: =IF(Sheet1!A17="","",Sheet1!A17) | B20: =IF(OR(Sheet1!B17="",Sheet1!B17=FALSE),"",Sheet1!B17) | C20: =IF(OR(Sheet1!C17="",Sheet1!C17=FALSE),"",Sheet1!C17) | D20: =IF(OR(Sheet1!D17="",Sheet1!D17=FALSE),"",Sheet1!D17) | E20: =IF(OR(Sheet1!E17="",Sheet1!E17=FALSE),"",Sheet1!E17) | F20: =IF(OR(Sheet1!F17="",Sheet1!F17=FALSE),"",Sheet1!F17) | G20: =IF(OR(Sheet1!G17="",Sheet1!G17=FALSE),"",Sheet1!G17) | H20: =IF(OR(Sheet1!H17="",Sheet1!H17=FALSE),"",Sheet1!H17) | I20: =IF(OR(#REF!="",#REF!=FALSE),"",#REF!) -> #REF! | J20: =IF(OR(Sheet1!I17="",Sheet1!I17=FALSE),"",Sheet1!I17) | K20: =IF(OR(Sheet1!J17="",Sheet1!J17=FALSE),"",Sheet1!J17) | L20: =IF(OR(Sheet1!K17="",Sheet1!K17=FALSE),"",Sheet1!K17) | M20: =IF(OR(Sheet1!L17="",Sheet1!L17=FALSE),"",Sheet1!L17)
A21: =IF(Sheet1!A18="","",Sheet1!A18) | B21: =IF(OR(Sheet1!B18="",Sheet1!B18=FALSE),"",Sheet1!B18) | C21: =IF(OR(Sheet1!C18="",Sheet1!C18=FALSE),"",Sheet1!C18) | D21: =IF(OR(Sheet1!D18="",Sheet1!D18=FALSE),"",Sheet1!D18) | E21: =IF(OR(Sheet1!E18="",Sheet1!E18=FALSE),"",Sheet1!E18) | F21: =IF(OR(Sheet1!F18="",Sheet1!F18=FALSE),"",Sheet1!F18) | G21: =IF(OR(Sheet1!G18="",Sheet1!G18=FALSE),"",Sheet1!G18) | H21: =IF(OR(Sheet1!H18="",Sheet1!H18=FALSE),"",Sheet1!H18) | I21: =IF(OR(#REF!="",#REF!=FALSE),"",#REF!) -> #REF! | J21: =IF(OR(Sheet1!I18="",Sheet1!I18=FALSE),"",Sheet1!I18) | K21: =IF(OR(Sheet1!J18="",Sheet1!J18=FALSE),"",Sheet1!J18) | L21: =IF(OR(Sheet1!K18="",Sheet1!K18=FALSE),"",Sheet1!K18) | M21: =IF(OR(Sheet1!L18="",Sheet1!L18=FALSE),"",Sheet1!L18)
A22: =IF(Sheet1!A19="","",Sheet1!A19) | B22: =IF(OR(Sheet1!B19="",Sheet1!B19=FALSE),"",Sheet1!B19) | C22: =IF(OR(Sheet1!C19="",Sheet1!C19=FALSE),"",Sheet1!C19) | D22: =IF(OR(Sheet1!D19="",Sheet1!D19=FALSE),"",Sheet1!D19) | E22: =IF(OR(Sheet1!E19="",Sheet1!E19=FALSE),"",Sheet1!E19) | F22: =IF(OR(Sheet1!F19="",Sheet1!F19=FALSE),"",Sheet1!F19) | G22: =IF(OR(Sheet1!G19="",Sheet1!G19=FALSE),"",Sheet1!G19) | H22: =IF(OR(Sheet1!H19="",Sheet1!H19=FALSE),"",Sheet1!H19) | I22: =IF(OR(#REF!="",#REF!=FALSE),"",#REF!) -> #REF! | J22: =IF(OR(Sheet1!I19="",Sheet1!I19=FALSE),"",Sheet1!I19) | K22: =IF(OR(Sheet1!J19="",Sheet1!J19=FALSE),"",Sheet1!J19) | L22: =IF(OR(Sheet1!K19="",Sheet1!K19=FALSE),"",Sheet1!K19) | M22: =IF(OR(Sheet1!L19="",Sheet1!L19=FALSE),"",Sheet1!L19)
A23: =IF(Sheet1!A20="","",Sheet1!A20) | B23: =IF(OR(Sheet1!B20="",Sheet1!B20=FALSE),"",Sheet1!B20) | C23: =IF(OR(Sheet1!C20="",Sheet1!C20=FALSE),"",Sheet1!C20) | D23: =IF(OR(Sheet1!D20="",Sheet1!D20=FALSE),"",Sheet1!D20) | E23: =IF(OR(Sheet1!E20="",Sheet1!E20=FALSE),"",Sheet1!E20) | F23: =IF(OR(Sheet1!F20="",Sheet1!F20=FALSE),"",Sheet1!F20) | G23: =IF(OR(Sheet1!G20="",Sheet1!G20=FALSE),"",Sheet1!G20) | H23: =IF(OR(Sheet1!H20="",Sheet1!H20=FALSE),"",Sheet1!H20) | I23: =IF(OR(#REF!="",#REF!=FALSE),"",#REF!) -> #REF! | J23: =IF(OR(Sheet1!I20="",Sheet1!I20=FALSE),"",Sheet1!I20) | K23: =IF(OR(Sheet1!J20="",Sheet1!J20=FALSE),"",Sheet1!J20) | L23: =IF(OR(Sheet1!K20="",Sheet1!K20=FALSE),"",Sheet1!K20) | M23: =IF(OR(Sheet1!L20="",Sheet1!L20=FALSE),"",Sheet1!L20)
A24: =IF(Sheet1!A21="","",Sheet1!A21) | B24: =IF(OR(Sheet1!B21="",Sheet1!B21=FALSE),"",Sheet1!B21) | C24: =IF(OR(Sheet1!C21="",Sheet1!C21=FALSE),"",Sheet1!C21) | D24: =IF(OR(Sheet1!D21="",Sheet1!D21=FALSE),"",Sheet1!D21) | E24: =IF(OR(Sheet1!E21="",Sheet1!E21=FALSE),"",Sheet1!E21) | F24: =IF(OR(Sheet1!F21="",Sheet1!F21=FALSE),"",Sheet1!F21) | G24: =IF(OR(Sheet1!G21="",Sheet1!G21=FALSE),"",Sheet1!G21) | H24: =IF(OR(Sheet1!H21="",Sheet1!H21=FALSE),"",Sheet1!H21) | I24: =IF(OR(#REF!="",#REF!=FALSE),"",#REF!) -> #REF! | J24: =IF(OR(Sheet1!I21="",Sheet1!I21=FALSE),"",Sheet1!I21) | K24: =IF(OR(Sheet1!J21="",Sheet1!J21=FALSE),"",Sheet1!J21) | L24: =IF(OR(Sheet1!K21="",Sheet1!K21=FALSE),"",Sheet1!K21) | M24: =IF(OR(Sheet1!L21="",Sheet1!L21=FALSE),"",Sheet1!L21)
A25: =IF(Sheet1!A22="","",Sheet1!A22) | B25: =IF(OR(Sheet1!B22="",Sheet1!B22=FALSE),"",Sheet1!B22) | C25: =IF(OR(Sheet1!C22="",Sheet1!C22=FALSE),"",Sheet1!C22) | D25: =IF(OR(Sheet1!D22="",Sheet1!D22=FALSE),"",Sheet1!D22) | E25: =IF(OR(Sheet1!E22="",Sheet1!E22=FALSE),"",Sheet1!E22) | F25: =IF(OR(Sheet1!F22="",Sheet1!F22=FALSE),"",Sheet1!F22) | G25: =IF(OR(Sheet1!G22="",Sheet1!G22=FALSE),"",Sheet1!G22) | H25: =IF(OR(Sheet1!H22="",Sheet1!H22=FALSE),"",Sheet1!H22) | I25: =IF(OR(#REF!="",#REF!=FALSE),"",#REF!) -> #REF! | J25: =IF(OR(Sheet1!I22="",Sheet1!I22=FALSE),"",Sheet1!I22) | K25: =IF(OR(Sheet1!J22="",Sheet1!J22=FALSE),"",Sheet1!J22) | L25: =IF(OR(Sheet1!K22="",Sheet1!K22=FALSE),"",Sheet1!K22) | M25: =IF(OR(Sheet1!L22="",Sheet1!L22=FALSE),"",Sheet1!L22)
A26: =IF(Sheet1!A23="","",Sheet1!A23) | B26: =IF(OR(Sheet1!B23="",Sheet1!B23=FALSE),"",Sheet1!B23) | C26: =IF(OR(Sheet1!C23="",Sheet1!C23=FALSE),"",Sheet1!C23) | D26: =IF(OR(Sheet1!D23="",Sheet1!D23=FALSE),"",Sheet1!D23) | E26: =IF(OR(Sheet1!E23="",Sheet1!E23=FALSE),"",Sheet1!E23) | F26: =IF(OR(Sheet1!F23="",Sheet1!F23=FALSE),"",Sheet1!F23) | G26: =IF(OR(Sheet1!G23="",Sheet1!G23=FALSE),"",Sheet1!G23) | H26: =IF(OR(Sheet1!H23="",Sheet1!H23=FALSE),"",Sheet1!H23) | I26: =IF(OR(#REF!="",#REF!=FALSE),"",#REF!) -> #REF! | J26: =IF(OR(Sheet1!I23="",Sheet1!I23=FALSE),"",Sheet1!I23) | K26: =IF(OR(Sheet1!J23="",Sheet1!J23=FALSE),"",Sheet1!J23) | L26: =IF(OR(Sheet1!K23="",Sheet1!K23=FALSE),"",Sheet1!K23) | M26: =IF(OR(Sheet1!L23="",Sheet1!L23=FALSE),"",Sheet1!L23)
A27: =IF(Sheet1!A24="","",Sheet1!A24) | B27: =IF(OR(Sheet1!B24="",Sheet1!B24=FALSE),"",Sheet1!B24) | C27: =IF(OR(Sheet1!C24="",Sheet1!C24=FALSE),"",Sheet1!C24) | D27: =IF(OR(Sheet1!D24="",Sheet1!D24=FALSE),"",Sheet1!D24) | E27: =IF(OR(Sheet1!E24="",Sheet1!E24=FALSE),"",Sheet1!E24) | F27: =IF(OR(Sheet1!F24="",Sheet1!F24=FALSE),"",Sheet1!F24) | G27: =IF(OR(Sheet1!G24="",Sheet1!G24=FALSE),"",Sheet1!G24) | H27: =IF(OR(Sheet1!H24="",Sheet1!H24=FALSE),"",Sheet1!H24) | I27: =IF(OR(#REF!="",#REF!=FALSE),"",#REF!) -> #REF! | J27: =IF(OR(Sheet1!I24="",Sheet1!I24=FALSE),"",Sheet1!I24) | K27: =IF(OR(Sheet1!J24="",Sheet1!J24=FALSE),"",Sheet1!J24) | L27: =IF(OR(Sheet1!K24="",Sheet1!K24=FALSE),"",Sheet1!K24) | M27: =IF(OR(Sheet1!L24="",Sheet1!L24=FALSE),"",Sheet1!L24)
A28: =IF(Sheet1!A25="","",Sheet1!A25) | B28: =IF(OR(Sheet1!B25="",Sheet1!B25=FALSE),"",Sheet1!B25) | C28: =IF(OR(Sheet1!C25="",Sheet1!C25=FALSE),"",Sheet1!C25) | D28: =IF(OR(Sheet1!D25="",Sheet1!D25=FALSE),"",Sheet1!D25) | E28: =IF(OR(Sheet1!E25="",Sheet1!E25=FALSE),"",Sheet1!E25) | F28: =IF(OR(Sheet1!F25="",Sheet1!F25=FALSE),"",Sheet1!F25) | G28: =IF(OR(Sheet1!G25="",Sheet1!G25=FALSE),"",Sheet1!G25) | H28: =IF(OR(Sheet1!H25="",Sheet1!H25=FALSE),"",Sheet1!H25) | I28: =IF(OR(#REF!="",#REF!=FALSE),"",#REF!) -> #REF! | J28: =IF(OR(Sheet1!I25="",Sheet1!I25=FALSE),"",Sheet1!I25) | K28: =IF(OR(Sheet1!J25="",Sheet1!J25=FALSE),"",Sheet1!J25) | L28: =IF(OR(Sheet1!K25="",Sheet1!K25=FALSE),"",Sheet1!K25) | M28: =IF(OR(Sheet1!L25="",Sheet1!L25=FALSE),"",Sheet1!L25)
A29: =IF(Sheet1!A26="","",Sheet1!A26) | B29: =IF(OR(Sheet1!B26="",Sheet1!B26=FALSE),"",Sheet1!B26) | C29: =IF(OR(Sheet1!C26="",Sheet1!C26=FALSE),"",Sheet1!C26) | D29: =IF(OR(Sheet1!D26="",Sheet1!D26=FALSE),"",Sheet1!D26) | E29: =IF(OR(Sheet1!E26="",Sheet1!E26=FALSE),"",Sheet1!E26) | F29: =IF(OR(Sheet1!F26="",Sheet1!F26=FALSE),"",Sheet1!F26) | G29: =IF(OR(Sheet1!G26="",Sheet1!G26=FALSE),"",Sheet1!G26) | H29: =IF(OR(Sheet1!H26="",Sheet1!H26=FALSE),"",Sheet1!H26) | I29: =IF(OR(#REF!="",#REF!=FALSE),"",#REF!) -> #REF! | J29: =IF(OR(Sheet1!I26="",Sheet1!I26=FALSE),"",Sheet1!I26) | K29: =IF(OR(Sheet1!J26="",Sheet1!J26=FALSE),"",Sheet1!J26) | L29: =IF(OR(Sheet1!K26="",Sheet1!K26=FALSE),"",Sheet1!K26) | M29: =IF(OR(Sheet1!L26="",Sheet1!L26=FALSE),"",Sheet1!L26)
A30: =IF(Sheet1!A27="","",Sheet1!A27) | B30: =IF(OR(Sheet1!B27="",Sheet1!B27=FALSE),"",Sheet1!B27) | C30: =IF(OR(Sheet1!C27="",Sheet1!C27=FALSE),"",Sheet1!C27) | D30: =IF(OR(Sheet1!D27="",Sheet1!D27=FALSE),"",Sheet1!D27) | E30: =IF(OR(Sheet1!E27="",Sheet1!E27=FALSE),"",Sheet1!E27) | F30: =IF(OR(Sheet1!F27="",Sheet1!F27=FALSE),"",Sheet1!F27) | G30: =IF(OR(Sheet1!G27="",Sheet1!G27=FALSE),"",Sheet1!G27) | H30: =IF(OR(Sheet1!H27="",Sheet1!H27=FALSE),"",Sheet1!H27) | I30: =IF(OR(#REF!="",#REF!=FALSE),"",#REF!) -> #REF! | J30: =IF(OR(Sheet1!I27="",Sheet1!I27=FALSE),"",Sheet1!I27) | K30: =IF(OR(Sheet1!J27="",Sheet1!J27=FALSE),"",Sheet1!J27) | L30: =IF(OR(Sheet1!K27="",Sheet1!K27=FALSE),"",Sheet1!K27) | M30: =IF(OR(Sheet1!L27="",Sheet1!L27=FALSE),"",Sheet1!L27)
A31: =IF(Sheet1!A28="","",Sheet1!A28) | B31: =IF(OR(Sheet1!B28="",Sheet1!B28=FALSE),"",Sheet1!B28) | C31: =IF(OR(Sheet1!C28="",Sheet1!C28=FALSE),"",Sheet1!C28) | D31: =IF(OR(Sheet1!D28="",Sheet1!D28=FALSE),"",Sheet1!D28) | E31: =IF(OR(Sheet1!E28="",Sheet1!E28=FALSE),"",Sheet1!E28) | F31: =IF(OR(Sheet1!F28="",Sheet1!F28=FALSE),"",Sheet1!F28) | G31: =IF(OR(Sheet1!G28="",Sheet1!G28=FALSE),"",Sheet1!G28) | H31: =IF(OR(Sheet1!H28="",Sheet1!H28=FALSE),"",Sheet1!H28) | I31: =IF(OR(#REF!="",#REF!=FALSE),"",#REF!) -> #REF! | J31: =IF(OR(Sheet1!I28="",Sheet1!I28=FALSE),"",Sheet1!I28) | K31: =IF(OR(Sheet1!J28="",Sheet1!J28=FALSE),"",Sheet1!J28) | L31: =IF(OR(Sheet1!K28="",Sheet1!K28=FALSE),"",Sheet1!K28) | M31: =IF(OR(Sheet1!L28="",Sheet1!L28=FALSE),"",Sheet1!L28)
... A39: =IF(Sheet1!A36="","",Sheet1!A36) | B39: =IF(OR(Sheet1!B36="",Sheet1!B36=FALSE),"",Sheet1!B36) | C39: =IF(OR(Sheet1!C36="",Sheet1!C36=FALSE),"",Sheet1!C36) | D39: =IF(OR(Sheet1!D36="",Sheet1!D36=FALSE),"",Sheet1!D36) | E39: =IF(OR(Sheet1!E36="",Sheet1!E36=FALSE),"",Sheet1!E36) | F39: =IF(OR(Sheet1!F36="",Sheet1!F36=FALSE),"",Sheet1!F36) | G39: =IF(OR(Sheet1!G36="",Sheet1!G36=FALSE),"",Sheet1!G36) | H39: =IF(OR(Sheet1!H36="",Sheet1!H36=FALSE),"",Sheet1!H36) | I39: =IF(OR(#REF!="",#REF!=FALSE),"",#REF!) -> #REF! | J39: =IF(OR(Sheet1!I36="",Sheet1!I36=FALSE),"",Sheet1!I36) | K39: =IF(OR(Sheet1!J36="",Sheet1!J36=FALSE),"",Sheet1!J36) | L39: =IF(OR(Sheet1!K36="",Sheet1!K36=FALSE),"",Sheet1!K36) | M39: =IF(OR(Sheet1!L36="",Sheet1!L36=FALSE),"",Sheet1!L36)
A40: =IF(#REF!="","",#REF!) -> #REF! | B40: =IF(OR(#REF!="",#REF!=FALSE),"",#REF!) -> #REF! | C40: =IF(OR(#REF!="",#REF!=FALSE),"",#REF!) -> #REF! | D40: =IF(OR(#REF!="",#REF!=FALSE),"",#REF!) -> #REF! | E40: =IF(OR(#REF!="",#REF!=FALSE),"",#REF!) -> #REF! | F40: =IF(OR(#REF!="",#REF!=FALSE),"",#REF!) -> #REF! | G40: =IF(OR(#REF!="",#REF!=FALSE),"",#REF!) -> #REF! | H40: =IF(OR(#REF!="",#REF!=FALSE),"",#REF!) -> #REF! | I40: =IF(OR(#REF!="",#REF!=FALSE),"",#REF!) -> #REF! | ... M40: =IF(OR(#REF!="",#REF!=FALSE),"",#REF!) -> #REF!
A41: =IF(Sheet1!A37="","",Sheet1!A37) | B41: =IF(OR(Sheet1!B37="",Sheet1!B37=FALSE),"",Sheet1!B37) | C41: =IF(OR(Sheet1!C37="",Sheet1!C37=FALSE),"",Sheet1!C37) | D41: =IF(OR(Sheet1!D37="",Sheet1!D37=FALSE),"",Sheet1!D37) | E41: =IF(OR(Sheet1!E37="",Sheet1!E37=FALSE),"",Sheet1!E37) | F41: =IF(OR(Sheet1!F37="",Sheet1!F37=FALSE),"",Sheet1!F37) | G41: =IF(OR(Sheet1!G37="",Sheet1!G37=FALSE),"",Sheet1!G37) | H41: =IF(OR(Sheet1!H37="",Sheet1!H37=FALSE),"",Sheet1!H37) | I41: =IF(OR(#REF!="",#REF!=FALSE),"",#REF!) -> #REF! | J41: =IF(OR(Sheet1!I37="",Sheet1!I37=FALSE),"",Sheet1!I37) | K41: =IF(OR(Sheet1!J37="",Sheet1!J37=FALSE),"",Sheet1!J37) | L41: =IF(OR(Sheet1!K37="",Sheet1!K37=FALSE),"",Sheet1!K37) | M41: =IF(OR(Sheet1!L37="",Sheet1!L37=FALSE),"",Sheet1!L37)
A42: =IF(Sheet1!A38="","",Sheet1!A38) | B42: =IF(OR(Sheet1!B38="",Sheet1!B38=FALSE),"",Sheet1!B38) | C42: =IF(OR(Sheet1!C38="",Sheet1!C38=FALSE),"",Sheet1!C38) | D42: =IF(OR(Sheet1!D38="",Sheet1!D38=FALSE),"",Sheet1!D38) | E42: =IF(OR(Sheet1!E38="",Sheet1!E38=FALSE),"",Sheet1!E38) | F42: =IF(OR(Sheet1!F38="",Sheet1!F38=FALSE),"",Sheet1!F38) | G42: =IF(OR(Sheet1!G38="",Sheet1!G38=FALSE),"",Sheet1!G38) | H42: =IF(OR(Sheet1!H38="",Sheet1!H38=FALSE),"",Sheet1!H38) | I42: =IF(OR(#REF!="",#REF!=FALSE),"",#REF!) -> #REF! | J42: =IF(OR(Sheet1!I38="",Sheet1!I38=FALSE),"",Sheet1!I38) | K42: =IF(OR(Sheet1!J38="",Sheet1!J38=FALSE),"",Sheet1!J38) | L42: =IF(OR(Sheet1!K38="",Sheet1!K38=FALSE),"",Sheet1!K38) | M42: =IF(OR(Sheet1!L38="",Sheet1!L38=FALSE),"",Sheet1!L38)
A43: =IF(Sheet1!A39="","",Sheet1!A39) | B43: =IF(OR(Sheet1!B39="",Sheet1!B39=FALSE),"",Sheet1!B39) | C43: =IF(OR(Sheet1!C39="",Sheet1!C39=FALSE),"",Sheet1!C39) | D43: =IF(OR(Sheet1!D39="",Sheet1!D39=FALSE),"",Sheet1!D39) | E43: =IF(OR(Sheet1!E39="",Sheet1!E39=FALSE),"",Sheet1!E39) | F43: =IF(OR(Sheet1!F39="",Sheet1!F39=FALSE),"",Sheet1!F39) | G43: =IF(OR(Sheet1!G39="",Sheet1!G39=FALSE),"",Sheet1!G39) | H43: =IF(OR(Sheet1!H39="",Sheet1!H39=FALSE),"",Sheet1!H39) | I43: =IF(OR(#REF!="",#REF!=FALSE),"",#REF!) -> #REF! | J43: =IF(OR(Sheet1!I39="",Sheet1!I39=FALSE),"",Sheet1!I39) | K43: =IF(OR(Sheet1!J39="",Sheet1!J39=FALSE),"",Sheet1!J39) | L43: =IF(OR(Sheet1!K39="",Sheet1!K39=FALSE),"",Sheet1!K39) | M43: =IF(OR(Sheet1!L39="",Sheet1!L39=FALSE),"",Sheet1!L39)
A44: =IF(Sheet1!A40="","",Sheet1!A40) | B44: =IF(OR(Sheet1!B40="",Sheet1!B40=FALSE),"",Sheet1!B40) | C44: =IF(OR(Sheet1!C40="",Sheet1!C40=FALSE),"",Sheet1!C40) | D44: =IF(OR(Sheet1!D40="",Sheet1!D40=FALSE),"",Sheet1!D40) | E44: =IF(OR(Sheet1!E40="",Sheet1!E40=FALSE),"",Sheet1!E40) | F44: =IF(OR(Sheet1!F40="",Sheet1!F40=FALSE),"",Sheet1!F40) | G44: =IF(OR(Sheet1!G40="",Sheet1!G40=FALSE),"",Sheet1!G40) | H44: =IF(OR(Sheet1!H40="",Sheet1!H40=FALSE),"",Sheet1!H40) | I44: =IF(OR(#REF!="",#REF!=FALSE),"",#REF!) -> #REF! | J44: =IF(OR(Sheet1!I40="",Sheet1!I40=FALSE),"",Sheet1!I40) | K44: =IF(OR(Sheet1!J40="",Sheet1!J40=FALSE),"",Sheet1!J40) | L44: =IF(OR(Sheet1!K40="",Sheet1!K40=FALSE),"",Sheet1!K40) | M44: =IF(OR(Sheet1!L40="",Sheet1!L40=FALSE),"",Sheet1!L40)
A45: =IF(Sheet1!A41="","",Sheet1!A41) | B45: =IF(OR(Sheet1!B41="",Sheet1!B41=FALSE),"",Sheet1!B41) | C45: =IF(OR(Sheet1!C41="",Sheet1!C41=FALSE),"",Sheet1!C41) | D45: =IF(OR(Sheet1!D41="",Sheet1!D41=FALSE),"",Sheet1!D41) | E45: =IF(OR(Sheet1!E41="",Sheet1!E41=FALSE),"",Sheet1!E41) | F45: =IF(OR(Sheet1!F41="",Sheet1!F41=FALSE),"",Sheet1!F41) | G45: =IF(OR(Sheet1!G41="",Sheet1!G41=FALSE),"",Sheet1!G41) | H45: =IF(OR(Sheet1!H41="",Sheet1!H41=FALSE),"",Sheet1!H41) | I45: =IF(OR(#REF!="",#REF!=FALSE),"",#REF!) -> #REF! | J45: =IF(OR(Sheet1!I41="",Sheet1!I41=FALSE),"",Sheet1!I41) | K45: =IF(OR(Sheet1!J41="",Sheet1!J41=FALSE),"",Sheet1!J41) | L45: =IF(OR(Sheet1!K41="",Sheet1!K41=FALSE),"",Sheet1!K41) | M45: =IF(OR(Sheet1!L41="",Sheet1!L41=FALSE),"",Sheet1!L41)
A46: =IF(Sheet1!A42="","",Sheet1!A42) | B46: =IF(OR(Sheet1!B42="",Sheet1!B42=FALSE),"",Sheet1!B42) | C46: =IF(OR(Sheet1!C42="",Sheet1!C42=FALSE),"",Sheet1!C42) | D46: =IF(OR(Sheet1!D42="",Sheet1!D42=FALSE),"",Sheet1!D42) | E46: =IF(OR(Sheet1!E42="",Sheet1!E42=FALSE),"",Sheet1!E42) | F46: =IF(OR(Sheet1!F42="",Sheet1!F42=FALSE),"",Sheet1!F42) | G46: =IF(OR(Sheet1!G42="",Sheet1!G42=FALSE),"",Sheet1!G42) | H46: =IF(OR(Sheet1!H42="",Sheet1!H42=FALSE),"",Sheet1!H42) | I46: =IF(OR(#REF!="",#REF!=FALSE),"",#REF!) -> #REF! | J46: =IF(OR(Sheet1!I42="",Sheet1!I42=FALSE),"",Sheet1!I42) | K46: =IF(OR(Sheet1!J42="",Sheet1!J42=FALSE),"",Sheet1!J42) | L46: =IF(OR(Sheet1!K42="",Sheet1!K42=FALSE),"",Sheet1!K42) | M46: =IF(OR(Sheet1!L42="",Sheet1!L42=FALSE),"",Sheet1!L42)
A47: =IF(Sheet1!A43="","",Sheet1!A43) | B47: =IF(OR(Sheet1!B43="",Sheet1!B43=FALSE),"",Sheet1!B43) | C47: =IF(OR(Sheet1!C43="",Sheet1!C43=FALSE),"",Sheet1!C43) | D47: =IF(OR(Sheet1!D43="",Sheet1!D43=FALSE),"",Sheet1!D43) | E47: =IF(OR(Sheet1!E43="",Sheet1!E43=FALSE),"",Sheet1!E43) | F47: =IF(OR(Sheet1!F43="",Sheet1!F43=FALSE),"",Sheet1!F43) | G47: =IF(OR(Sheet1!G43="",Sheet1!G43=FALSE),"",Sheet1!G43) | H47: =IF(OR(Sheet1!H43="",Sheet1!H43=FALSE),"",Sheet1!H43) | I47: =IF(OR(#REF!="",#REF!=FALSE),"",#REF!) -> #REF! | J47: =IF(OR(Sheet1!I43="",Sheet1!I43=FALSE),"",Sheet1!I43) | K47: =IF(OR(Sheet1!J43="",Sheet1!J43=FALSE),"",Sheet1!J43) | L47: =IF(OR(Sheet1!K43="",Sheet1!K43=FALSE),"",Sheet1!K43) | M47: =IF(OR(Sheet1!L43="",Sheet1!L43=FALSE),"",Sheet1!L43)
...

Sheet Sheet3
